<?xml version="1.0" ?>
<!-- ======================================================================= -->
<!-- | This document was autogenerated by xacro from lbr_iiwa.urdf.xacro   | -->
<!-- | Original xacro: https://github.com/rtkg/lbr_iiwa/archive/master.zip | -->
<!-- | EDITING THIS FILE BY HAND IS NOT RECOMMENDED                        | -->
<!-- | Changes (kohlhoff):                                                 | -->
<!-- |   * Removed gazebo tags.                                            | -->
<!-- |   * Removed unused materials.                                       | -->
<!-- |   * Made mesh paths relative.                                       | -->
<!-- |   * Removed material fields from collision segments.                | -->
<!-- |   * Removed the self_collision_checking segment.                    | -->
<!-- |   * Removed transmission segments, since they didn't match the      | -->
<!-- |     convention, will have to added back later.                      | -->
<!-- ======================================================================= -->
<!--LICENSE:                                                                 -->
<!--Copyright (c) 2015, Robert Krug & Todor Stoyanov, AASS Research Center,  -->
<!--Orebro University, Sweden                                                -->
<!--All rights reserved.                                                     -->
<!--                                                                         -->
<!--Redistribution and use in source and binary forms, with or without       -->
<!--modification, are permitted provided that the following conditions are   -->
<!--met:                                                                     -->
<!--                                                                         -->
<!--1. Redistributions of source code must retain the above copyright notice,-->
<!--   this list of conditions and the following disclaimer.                 -->
<!--                                                                         -->
<!--2. Redistributions in binary form must reproduce the above copyright     -->
<!--   notice, this list of conditions and the following disclaimer in the   -->
<!--   documentation and/or other materials provided with the distribution.  -->
<!--                                                                         -->
<!--THIS SOFTWARE IS PROVIDED BY THE COPYRIGHT HOLDERS AND CONTRIBUTORS "AS  -->
<!--IS" AND ANY EXPRESS OR IMPLIED WARRANTIES, INCLUDING, BUT NOT LIMITED TO,-->
<!--THE IMPLIED WARRANTIES OF MERCHANTABILITY AND FITNESS FOR A PARTICULAR   -->
<!--PURPOSE ARE DISCLAIMED. IN NO EVENT SHALL THE COPYRIGHT HOLDER OR        -->
<!--CONTRIBUTORS BE LIABLE FOR ANY DIRECT, INDIRECT, INCIDENTAL, SPECIAL,    -->
<!--EXEMPLARY, OR CONSEQUENTIAL DAMAGES (INCLUDING, BUT NOT LIMITED TO,      -->
<!--PROCUREMENT OF SUBSTITUTE GOODS OR SERVICES; LOSS OF USE, DATA, OR       -->
<!--PROFITS; OR BUSINESS INTERRUPTION) HOWEVER CAUSED AND ON ANY THEORY OF   -->
<!--LIABILITY, WHETHER IN CONTRACT, STRICT LIABILITY, OR TORT (INCLUDING     -->
<!--NEGLIGENCE OR OTHERWISE) ARISING IN ANY WAY OUT OF THE USE OF THIS       -->
<!--SOFTWARE, EVEN IF ADVISED OF THE POSSIBILITY OF SUCH DAMAGE.             -->
<robot name="lbr_iiwa" xmlns:xacro="http://www.ros.org/wiki/xacro">
  <!-- Import Rviz colors -->
  <mujoco>
    <compiler meshdir="iiwa_description/visual" balanceinertia="false" discardvisual="false"/>
  </mujoco>
  <material name="Grey">
    <color rgba="0.2 0.2 0.2 1.0"/>
  </material>
  <material name="Orange">
    <color rgba="1.0 0.423529411765 0.0392156862745 1.0"/>
  </material>
  <material name="Blue">
  <color rgba="0.5 0.7 1.0 1.0"/>      
</material>

  <!--Import the lbr iiwa macro -->
  <!--Import Transmissions -->
  <!--Include Utilities -->
  <!--The following macros are adapted from the LWR 4 definitions of the RCPRG - https://github.com/RCPRG-ros-pkg/lwr_robot -->
  <!--Little helper macros to define the inertia matrix needed for links.-->
  <!--Cuboid-->
  <!--Cylinder: length is along the y-axis! -->
  <!--lbr-->
  <link name="lbr_iiwa_link_0">
    <inertial>
      <origin rpy="0 0 0" xyz="-0.1 0 0.07"/>
      <!--Increase mass from 5 Kg original to provide a stable base to carry the
          arm.-->
      <mass value="1.0"/>
      <inertia ixx="0.05" ixy="0" ixz="0" iyy="0.06" iyz="0" izz="0.03"/>
    </inertial>
    <visual>
      <origin rpy="0 0 0" xyz="0 0 0"/>
      <geometry>
        <mesh filename="iiwa_description/visual/link_0.stl"/>
      </geometry>
      <material name="Grey"/>
    </visual>
    <collision>
      <origin rpy="0 0 0" xyz="0 0 0"/>
      <geometry>
        <mesh filename="iiwa_description/collision/link_0.obj"/>
      </geometry>
    </collision>
  </link>
  <!-- joint between link_0 and link_1 -->
  <joint name="lbr_iiwa_joint_1" type="revolute">
    <parent link="lbr_iiwa_link_0"/>
    <child link="lbr_iiwa_link_1"/>
    <origin rpy="0 0 0" xyz="0 0 0.1575"/>
    <axis xyz="0 0 1"/>
    <limit effort="300" lower="-2.96705972839" upper="2.96705972839" velocity="10"/>
    <dynamics damping="0.5"/>
  </joint>
  <link name="lbr_iiwa_link_1">
    <inertial>
      <origin rpy="0 0 0" xyz="0 -0.03 0.12"/>
      <mass value="4"/>
      <inertia ixx="0.1" ixy="0" ixz="0" iyy="0.09" iyz="0" izz="0.02"/>
    </inertial>
    <visual>
      <origin rpy="0 0 0" xyz="0 0 0"/>
      <geometry>
        <mesh filename="iiwa_description/visual/link_1.stl"/>
      </geometry>
      <material name="Blue"/>
    </visual>
    <collision>
      <origin rpy="0 0 0" xyz="0 0 0"/>
      <geometry>
        <mesh filename="iiwa_description/collision/link_1.stl"/>
      </geometry>
    </collision>
  </link>
  <!-- joint between link_1 and link_2 -->
  <joint name="lbr_iiwa_joint_2" type="revolute">
    <parent link="lbr_iiwa_link_1"/>
    <child link="lbr_iiwa_link_2"/>
    <origin rpy="1.57079632679   0 3.14159265359" xyz="0 0 0.2025"/>
    <axis xyz="0 0 1"/>
    <limit effort="300" lower="-2.09439510239" upper="2.09439510239" velocity="10"/>
    <dynamics damping="0.5"/>
  </joint>
  <link name="lbr_iiwa_link_2">
    <inertial>
      <origin rpy="0 0 0" xyz="0.0003 0.059 0.042"/>
      <mass value="4"/>
      <inertia ixx="0.05" ixy="0" ixz="0" iyy="0.018" iyz="0" izz="0.044"/>
    </inertial>
    <visual>
      <origin rpy="0 0 0" xyz="0 0 0"/>
      <geometry>
        <mesh filename="iiwa_description/visual/link_2.stl"/>
      </geometry>
      <material name="Blue"/>
    </visual>
    <collision>
      <origin rpy="0 0 0" xyz="0 0 0"/>
      <geometry>
        <mesh filename="iiwa_description/collision/link_2.stl"/>
      </geometry>
    </collision>
  </link>
  <!-- joint between link_2 and link_3 -->
  <joint name="lbr_iiwa_joint_3" type="revolute">
    <parent link="lbr_iiwa_link_2"/>
    <child link="lbr_iiwa_link_3"/>
    <origin rpy="1.57079632679 0 3.14159265359" xyz="0 0.2045 0"/>
    <axis xyz="0 0 1"/>
    <limit effort="300" lower="-2.96705972839" upper="2.96705972839" velocity="10"/>
    <dynamics damping="0.5"/>
  </joint>
  <link name="lbr_iiwa_link_3">
    <inertial>
      <origin rpy="0 0 0" xyz="0 0.03 0.13"/>
      <mass value="3"/>
      <inertia ixx="0.08" ixy="0" ixz="0" iyy="0.075" iyz="0" izz="0.01"/>
    </inertial>
    <visual>
      <origin rpy="0 0 0" xyz="0 0 0"/>
      <geometry>
        <mesh filename="iiwa_description/visual/link_3.stl"/>
      </geometry>
      <material name="Orange"/>
    </visual>
    <collision>
      <origin rpy="0 0 0" xyz="0 0 0"/>
      <geometry>
        <mesh filename="iiwa_description/collision/link_3.stl"/>
      </geometry>
    </collision>
  </link>
  <!-- joint between link_3 and link_4 -->
  <joint name="lbr_iiwa_joint_4" type="revolute">
    <parent link="lbr_iiwa_link_3"/>
    <child link="lbr_iiwa_link_4"/>
    <origin rpy="1.57079632679 0 0" xyz="0 0 0.2155"/>
    <axis xyz="0 0 1"/>
    <limit effort="300" lower="-2.09439510239" upper="2.09439510239" velocity="10"/>
    <dynamics damping="0.5"/>
  </joint>
  <link name="lbr_iiwa_link_4">
    <inertial>
      <origin rpy="0 0 0" xyz="0 0.067 0.034"/>
      <mass value="2.7"/>
      <inertia ixx="0.03" ixy="0" ixz="0" iyy="0.01" iyz="0" izz="0.029"/>
    </inertial>
    <visual>
      <origin rpy="0 0 0" xyz="0 0 0"/>
      <geometry>
        <mesh filename="iiwa_description/visual/link_4.stl"/>
      </geometry>
      <material name="Blue"/>
    </visual>
    <collision>
      <origin rpy="0 0 0" xyz="0 0 0"/>
      <geometry>
        <mesh filename="iiwa_description/collision/link_4.stl"/>
      </geometry>
    </collision>
  </link>
  <!-- joint between link_4 and link_5 -->S
  <joint name="lbr_iiwa_joint_5" type="revolute">
    <parent link="lbr_iiwa_link_4"/>
    <child link="lbr_iiwa_link_5"/>
    <origin rpy="-1.57079632679 3.14159265359 0" xyz="0 0.1845 0"/>
    <axis xyz="0 0 1"/>
    <limit effort="300" lower="-2.96705972839" upper="2.96705972839" velocity="10"/>
    <dynamics damping="0.5"/>
  </joint>
  <link name="lbr_iiwa_link_5">
    <inertial>
      <origin rpy="0 0 0" xyz="0.0001 0.021 0.076"/>
      <mass value="1.7"/>
      <inertia ixx="0.02" ixy="0" ixz="0" iyy="0.018" iyz="0" izz="0.005"/>
    </inertial>
    <visual>
      <origin rpy="0 0 0" xyz="0 0 0"/>
      <geometry>
        <mesh filename="iiwa_description/visual/link_5.stl"/>
      </geometry>
      <material name="Blue"/>
    </visual>
    <collision>
      <origin rpy="0 0 0" xyz="0 0 0"/>
      <geometry>
        <mesh filename="iiwa_description/collision/link_5.stl"/>
      </geometry>
    </collision>
  </link>
  <!-- joint between link_5 and link_6 -->
  <joint name="lbr_iiwa_joint_6" type="revolute">
    <parent link="lbr_iiwa_link_5"/>
    <child link="lbr_iiwa_link_6"/>
    <origin rpy="1.57079632679 0 0" xyz="0 0 0.2155"/>
    <axis xyz="0 0 1"/>
    <limit effort="300" lower="-2.09439510239" upper="2.09439510239" velocity="10"/>
    <dynamics damping="0.5"/>
  </joint>
  <link name="lbr_iiwa_link_6">
    <inertial>
      <origin rpy="0 0 0" xyz="0 0.0006 0.0004"/>
      <mass value="1.8"/>
      <inertia ixx="0.005" ixy="0" ixz="0" iyy="0.0036" iyz="0" izz="0.0047"/>
    </inertial>
    <visual>
      <origin rpy="0 0 0" xyz="0 0 0"/>
      <geometry>
        <mesh filename="iiwa_description/visual/link_6.stl"/>
      </geometry>
      <material name="Orange"/>
    </visual>
    <collision>
      <origin rpy="0 0 0" xyz="0 0 0"/>
      <geometry>
        <mesh filename="iiwa_description/collision/link_6.stl"/>
      </geometry>
    </collision>
  </link>
  <!-- joint between link_6 and link_7 -->
  <joint name="lbr_iiwa_joint_7" type="revolute">
    <parent link="lbr_iiwa_link_6"/>
    <child link="lbr_iiwa_link_7"/>
    <origin rpy="-1.57079632679 3.14159265359 0" xyz="0 0.081 0"/>
    <axis xyz="0 0 1"/>
    <limit effort="300" lower="-3.05432619099" upper="3.05432619099" velocity="10"/>
    <dynamics damping="0.5"/>
  </joint>
  <link name="lbr_iiwa_link_7">
    <inertial>
      <origin rpy="0 0 0" xyz="0 0 0.02"/>
      <mass value="0.3"/>
      <inertia ixx="0.001" ixy="0" ixz="0" iyy="0.001" iyz="0" izz="0.001"/>
    </inertial>
    <visual>
      <origin rpy="0 0 0" xyz="0 0 0"/>
      <geometry>
        <mesh filename="iiwa_description/visual/link_7.stl"/>
      </geometry>
      <material name="Grey"/>
    </visual>
    <collision>
      <origin rpy="0 0 0" xyz="0 0 0"/>
      <geometry>
        <mesh filename="iiwa_description/collision/link_7.stl"/>
      </geometry>
    </collision>
  </link>
  <joint name="iiwa_joint_ee" type="fixed">
    <parent link="lbr_iiwa_link_7"/>
    <child link="iiwa_link_ee_kuka"/>
    <origin rpy="3.141592653589793 3.141592653589793 3.141592653589793" xyz="0 0 0.12"/>
    <axis xyz="0 0 1"/>
  </joint>
  <link name="iiwa_link_ee_kuka">
    </link>
  <joint name="tool0_joint" type="fixed">
    <parent link="lbr_iiwa_link_7"/>
    <child link="base_link"/>
    <origin rpy="0 0 0" xyz="0 0 0.04"/>
  </joint>
  <link name="base_link">
    <inertial>
      <origin xyz="-1.53444878605399E-05 -0.00277693660903533 0.0352882290973172" rpy="0 0 0"/>
      <mass value="0.377966381303299"/>
      <inertia ixx="0.000427326373018601" ixy="2.6443337984506E-07" ixz="-2.02908063714989E-07" iyy="0.000361316175967098" iyz="-3.0792687327603E-05" izz="0.000376798128588446"/>
    </inertial>
    <visual>
      <origin xyz="0 0 0" rpy="0 0 0"/>
      <geometry>
        <mesh filename="barret_description/visual/base_link.glb"/>
      </geometry>
    </visual>
    <collision> <!-- base_cylinder -->
      <origin xyz="0 0 0" rpy="0 0 0"/>
      <geometry>
        <mesh filename="barret_description/collision/base_link_cylinder.obj"/>
      </geometry>
    </collision>
    <collision> <!-- base_link -->
      <origin xyz="0 -0.011 0.054" rpy="0 0 0"/>
      <geometry>
        <box size="0.026 0.108 0.026"/>
      </geometry>
    </collision>
    <collision>
      <origin xyz="0 0 0.072" rpy="0 0 0"/>
      <geometry>
        <box size="0.076 0.046 0.014"/>
      </geometry>
    </collision>
    <collision>
      <origin xyz="0 0.032 0.068" rpy="-0.39 0 0"/>
      <geometry>
        <box size="0.026 0.02 0.01"/>
      </geometry>
    </collision>
    <collision>
      <origin xyz="0 -0.035 0.07" rpy="-1.03 0 0"/>
      <geometry>
        <box size="0.026 0.02 0.01"/>
      </geometry>
    </collision>
  </link>
  <link name="finger_1_prox_link">
    <inertial>
      <origin xyz="-0.0288648917008988 9.98379746692153E-05 0.0171253477569802" rpy="0 0 0"/>
      <mass value="56143.0626955765E-5"/>
      <inertia ixx="10.4484040652085E-5" ixy="-0.117861448219975E-5" ixz="-5.31613760585343E-5" iyy="33.9552353012776E-5" iyz="0.0780041192837706E-5" izz="29.3669090518615E-5"/>
    </inertial>
    <visual>
      <origin xyz="0 0 0" rpy="0 0 0"/>
      <geometry>
        <mesh filename="barret_description/visual/prox_link.glb"/>
      </geometry>
    </visual>
    <collision>   <!-- finger1_prox_link -->
      <origin xyz="0 0 0" rpy="0 0 0"/>
      <geometry>
        <mesh filename="barret_description/collision/prox_link_cylinder.obj"/>
      </geometry>
    </collision>
    <collision>
      <origin xyz="-0.029 0 0.012" rpy="0 0 0"/>
      <geometry>
        <box size="0.07 0.024 0.026"/>
      </geometry>
    </collision>
    <collision>
      <origin xyz="-0.036 0 0.03" rpy="0 1.029 0"/>
      <geometry>
        <box size="0.02 0.026 0.01"/>
      </geometry>
    </collision>
  </link>
  <joint name="finger_1_prox_joint" type="revolute">
    <origin xyz="0.025 0 0.0415" rpy="0 2.7051E-17 -1.5708"/>
    <parent link="base_link"/>
    <child link="finger_1_prox_link"/>
    <axis xyz="0 0 1"/>
    <limit lower="-3.141" upper="0" effort="0" velocity="10"/>
  </joint>
  <link name="finger_1_med_link">
    <inertial>
      <origin xyz="-0.030918176135544 0.0019693024932544 0.000743369842666108" rpy="0 0 0"/>
      <mass value="31321.1214212939E-5"/>
      <inertia ixx="2.18512832127284E-5" ixy="-0.844484268309696E-5" ixz="0.0135401272401385E-5" iyy="17.3596441998536E-5" iyz="-0.001126692167519E-5" izz="17.7656644395659E-5"/>
    </inertial>
    <visual>
      <origin xyz="0 0 0" rpy="0 0 0"/>
      <geometry>
        <mesh filename="barret_description/visual/med_link.glb"/>
      </geometry>
    </visual>
    <collision> <!-- finger1_med_link -->
      <origin xyz="-0.04 0.003 0.001" rpy="0 0 0"/>
      <geometry>
        <box size="0.036 0.024 0.018"/>
      </geometry>
    </collision>
    <collision>
      <origin xyz="-0.006 0.001 0.001" rpy="0 0 0"/>
      <geometry>
        <box size="0.032 0.022 0.01"/>
      </geometry>
    </collision>
    <collision>
      <origin xyz="-0.068 0.003 0.001" rpy="0 0 0"/>
      <geometry>
        <box size="0.02 0.022 0.01"/>
      </geometry>
    </collision>
    <collision>
      <origin xyz="-0.019 0.001 0.001" rpy="0 0 0"/>
      <geometry>
        <box size="0.008 0.022 0.018"/>
      </geometry>
    </collision>
  </link>
  <joint name="finger_1_med_joint" type="revolute">
    <origin xyz="-0.05 0 0.0339" rpy="1.5708 -8.8281E-17 0"/>
    <parent link="finger_1_prox_link"/>
    <child link="finger_1_med_link"/>
    <axis xyz="0 0 1"/>
    <limit lower="-2.44" upper="0" effort="0" velocity="10"/>
  </joint>
  <link name="finger_1_dist_link">
    <inertial>
      <origin xyz="-0.018331495851456 0.017563370050582 0.000497127783315291" rpy="0 0 0"/>
      <mass value="19342.3312257343E-5"/>
      <inertia ixx="3.67466110522623E-5" ixy="-2.57800680786605E-5" ixz="-0.0345727635031181E-5" iyy="4.08727012680705E-5" iyz="0.0329223427372985E-5" izz="5.99395386650428E-5"/>
    </inertial>
    <visual>
      <origin xyz="0 0 0" rpy="0 0 0"/>
      <geometry>
        <mesh filename="barret_description/visual/dist_link.glb"/>
      </geometry>
    </visual>
    <collision> <!-- finger1_disk_link -->
      <origin xyz="-0.022 0.023 0" rpy="0 0 0.8988"/>
      <geometry>
        <box size="0.014 0.038 0.02"/>
      </geometry>
    </collision>
    <collision>
      <origin xyz="-0.002 0.002 0" rpy="0 0 0.7766"/>
      <geometry>
        <box size="0.018 0.022 0.02"/>
      </geometry>
    </collision>
    <collision>
      <origin xyz="-0.038 0.034 0" rpy="0 0 1.614"/>
      <geometry>
        <box size="0.012 0.012 0.02"/>
      </geometry>
    </collision>
  </link>
  <joint name="finger_1_dist_joint" type="revolute">
    <origin xyz="-0.069936 0.003 0" rpy="1.6787E-18 -3.6382E-15 -6.1073E-33"/>
    <parent link="finger_1_med_link"/>
    <child link="finger_1_dist_link"/>
    <axis xyz="0 0 1"/>
    <limit lower="-0.785" upper="0" effort="0" velocity="10"/>
  </joint>
  <joint name="weld_finger_1_tip" type="fixed">
    <origin rpy="0 0 0" xyz="-0.04 0.04 0.0"/>
    <parent link="finger_1_dist_link"/>
    <child link="finger_1_tip"/>
  </joint>
  <link name="finger_1_tip">
  </link>
  <link name="finger_2_prox_link">
    <inertial>
      <origin xyz="-0.0288648917008987 9.98379746692118E-05 0.0171253477569802" rpy="0 0 0"/>
      <mass value="56143.0626955765E-5"/>
      <inertia ixx="10.4484040652085E-5" ixy="-0.117861448219975E-5" ixz="-5.31613760585343E-5" iyy="33.9552353012776E-5" iyz="0.0780041192837701E-5" izz="29.3669090518615E-5"/>
    </inertial>
    <visual>
      <origin xyz="0 0 0" rpy="0 0 0"/>
      <geometry>
        <mesh filename="barret_description/visual/prox_link.glb"/>
      </geometry>
    </visual>
    <collision>   <!-- finger2_prox_link -->
      <origin xyz="0 0 0" rpy="0 0 0"/>
      <geometry>
        <mesh filename="barret_description/collision/prox_link_cylinder.obj"/>
      </geometry>
    </collision>
    <collision>
      <origin xyz="-0.029 0 0.012" rpy="0 0 0"/>
      <geometry>
        <box size="0.07 0.024 0.026"/>
      </geometry>
    </collision>
    <collision>
      <origin xyz="-0.036 0 0.03" rpy="0 1.029 0"/>
      <geometry>
        <box size="0.02 0.026 0.01"/>
      </geometry>
    </collision>
  </link>
  <joint name="finger_2_prox_joint" type="revolute">
    <origin xyz="-0.025 0 0.0415" rpy="0 2.7051E-17 -1.5708"/>
    <parent link="base_link"/>
    <child link="finger_2_prox_link"/>
    <axis xyz="0 0 1"/>
    <limit lower="0" upper="3.141" effort="0" velocity="10"/>
  </joint>
  <link name="finger_2_med_link">
    <inertial>
      <origin xyz="-0.0309061378225848 0.00214997948654991 0.000743369814045599" rpy="0 0 0"/>
      <mass value="31321.1215499126E-5"/>
      <inertia ixx="2.19551825824831E-5" ixy="-0.933117181988174E-5" ixz="0.0135333166873642E-5" iyy="17.3492542935561E-5" iyz="-0.00120585854514789E-5" izz="17.7656644132238E-5"/>
    </inertial>
    <visual>
      <origin xyz="0 0 0" rpy="0 0 0"/>
      <geometry>
        <mesh filename="barret_description/visual/med_link.glb"/>
      </geometry>
    </visual>
    <collision> <!-- finger2_med_link -->
      <origin xyz="-0.04 0.003 0.001" rpy="0 0 0"/>
      <geometry>
        <box size="0.036 0.024 0.018"/>
      </geometry>
    </collision>
    <collision>
      <origin xyz="-0.006 0.001 0.001" rpy="0 0 0"/>
      <geometry>
        <box size="0.032 0.022 0.01"/>
      </geometry>
    </collision>
    <collision>
      <origin xyz="-0.068 0.003 0.001" rpy="0 0 0"/>
      <geometry>
        <box size="0.02 0.022 0.01"/>
      </geometry>
    </collision>
    <collision>
      <origin xyz="-0.019 0.001 0.001" rpy="0 0 0"/>
      <geometry>
        <box size="0.008 0.022 0.018"/>
      </geometry>
    </collision>
  </link>
  <joint name="finger_2_med_joint" type="revolute">
    <origin xyz="-0.05 0 0.0339" rpy="1.5708 -8.8281E-17 0"/>
    <parent link="finger_2_prox_link"/>
    <child link="finger_2_med_link"/>
    <axis xyz="0 0 1"/>
    <limit lower="-2.44" upper="0" effort="0" velocity="10"/>
  </joint>
  <link name="finger_2_dist_link">
    <inertial>
      <origin xyz="-0.0181940669984822 0.017705695005231 0.000497127783261171" rpy="0 0 0"/>
      <mass value="19342.3313295693E-5"/>
      <inertia ixx="3.71486604025429E-5" ixy="-2.58090906930852E-5" ixz="-0.0343151446338957E-5" iyy="4.04706522522361E-5" iyz="0.0331907761165059E-5" izz="5.99395390717116E-5"/>
    </inertial>
    <visual>
      <origin xyz="0 0 0" rpy="0 0 0"/>
      <geometry>
        <mesh filename="barret_description/visual/dist_link.glb"/>
      </geometry>
    </visual>
    <collision> <!-- finger2_disk_link -->
      <origin xyz="-0.022 0.023 0" rpy="0 0 0.8988"/>
      <geometry>
        <box size="0.014 0.038 0.02"/>
      </geometry>
    </collision>
    <collision>
      <origin xyz="-0.002 0.002 0" rpy="0 0 0.7766"/>
      <geometry>
        <box size="0.018 0.022 0.02"/>
      </geometry>
    </collision>
    <collision>
      <origin xyz="-0.038 0.034 0" rpy="0 0 1.614"/>
      <geometry>
        <box size="0.012 0.012 0.02"/>
      </geometry>
    </collision>
  </link>
  <joint name="finger_2_dist_joint" type="revolute">
    <origin xyz="-0.069917 0.0034087 0" rpy="-3.1382E-17 -2.3229E-16 0"/>
    <parent link="finger_2_med_link"/>
    <child link="finger_2_dist_link"/>
    <axis xyz="0 0 1"/>
    <limit lower="-0.785" upper="0" effort="0" velocity="10"/>
  </joint>
  <joint name="weld_finger_2_tip" type="fixed">
    <origin rpy="0 0 0" xyz="-0.04 0.04 0.0"/>
    <parent link="finger_2_dist_link"/>
    <child link="finger_2_tip"/>
  </joint>
  <link name="finger_2_tip">
  </link>
  <link name="finger_3_med_link">
    <inertial>
      <origin xyz="-0.0309181761355441 0.00196930249325443 0.000743369842666415" rpy="0 0 0"/>
      <mass value="31321.121421294E-5"/>
      <inertia ixx="2.18512832127284E-5" ixy="-0.844484268309696E-5" ixz="0.0135401272400822E-5" iyy="17.3596441998537E-5" iyz="-0.0011266921675151E-5" izz="17.7656644395659E-5"/>
    </inertial>
    <visual>
      <origin xyz="0 0 0" rpy="0 0 0"/>
      <geometry>
        <mesh filename="barret_description/visual/med_link.glb"/>
      </geometry>
    </visual>
    <collision> <!-- finger3_med_link -->
      <origin xyz="-0.04 0.003 0.001" rpy="0 0 0"/>
      <geometry>
        <box size="0.036 0.024 0.018"/>
      </geometry>
    </collision>
    <collision>
      <origin xyz="-0.006 0.001 0.001" rpy="0 0 0"/>
      <geometry>
        <box size="0.032 0.022 0.01"/>
      </geometry>
    </collision>
    <collision>
      <origin xyz="-0.068 0.003 0.001" rpy="0 0 0"/>
      <geometry>
        <box size="0.02 0.022 0.01"/>
      </geometry>
    </collision>
    <collision>
      <origin xyz="-0.019 0.001 0.001" rpy="0 0 0"/>
      <geometry>
        <box size="0.008 0.022 0.018"/>
      </geometry>
    </collision>
  </link>
  <joint name="finger_3_med_joint" type="revolute">
    <origin xyz="0 -0.05 0.0754" rpy="1.5708 6.123E-17 1.5708"/>
    <parent link="base_link"/>
    <child link="finger_3_med_link"/>
    <axis xyz="0 0 1"/>
    <limit lower="-2.44" upper="0" effort="0" velocity="10"/>
  </joint>
  <link name="finger_3_dist_link">
    <inertial>
      <origin xyz="-0.0183314958518909 0.0175633700501297 0.000497127783323787" rpy="0 0 0"/>
      <mass value="19342.3312257343E-5"/>
      <inertia ixx="3.67466110509902E-5" ixy="-2.57800680785588E-5" ixz="-0.0345727635040649E-5" iyy="4.08727012693427E-5" iyz="0.0329223427365976E-5" izz="5.99395386650428E-5"/>
    </inertial>
    <visual>
      <origin xyz="0 0 0" rpy="0 0 0"/>
      <geometry>
        <mesh filename="barret_description/visual/dist_link.glb"/>
      </geometry>
    </visual>
    <collision> <!-- finger3_disk_link -->
      <origin xyz="-0.022 0.023 0" rpy="0 0 0.8988"/>
      <geometry>
        <box size="0.014 0.038 0.02"/>
      </geometry>
    </collision>
    <collision>
      <origin xyz="-0.002 0.002 0" rpy="0 0 0.7766"/>
      <geometry>
        <box size="0.018 0.022 0.02"/>
      </geometry>
    </collision>
    <collision>
      <origin xyz="-0.038 0.034 0" rpy="0 0 1.614"/>
      <geometry>
        <box size="0.012 0.012 0.02"/>
      </geometry>
    </collision>
  </link>
  <joint name="finger_3_dist_joint" type="revolute">
    <origin xyz="-0.069936 0.003 0" rpy="6.0427E-17 -6.7283E-18 -4.0657E-34"/>
    <parent link="finger_3_med_link"/>
    <child link="finger_3_dist_link"/>
    <axis xyz="0 0 1"/>
    <limit lower="-0.785" upper="0" effort="0" velocity="10"/>
  </joint>
  <joint name="weld_finger_3_tip" type="fixed">
    <origin rpy="0 0 0" xyz="-0.04 0.04 0.0"/>
    <parent link="finger_3_dist_link"/>
    <child link="finger_3_tip"/>
  </joint>
  <link name="finger_3_tip">
  </link>
  <link name="palm_center">
  </link>
  <joint name="palm_center_joint" type="fixed">
    <parent link="lbr_iiwa_link_7"/>
    <child link="palm_center"/>
    <origin rpy="3.141592653589793 3.141592653589793 3.141592653589793" xyz="0 0 0.13"/>
  </joint>
</robot>
