<?xml version="1.0" ?>
<!-- ======================================================================= -->
<!-- | This document was autogenerated by xacro from lbr_iiwa.urdf.xacro   | -->
<!-- | Original xacro: https://github.com/rtkg/lbr_iiwa/archive/master.zip | -->
<!-- | EDITING THIS FILE BY HAND IS NOT RECOMMENDED                        | -->
<!-- | Changes (kohlhoff):                                                 | -->
<!-- |   * Removed gazebo tags.                                            | -->
<!-- |   * Removed unused materials.                                       | -->
<!-- |   * Made mesh paths relative.                                       | -->
<!-- |   * Removed material fields from collision segments.                | -->
<!-- |   * Removed the self_collision_checking segment.                    | -->
<!-- |   * Removed transmission segments, since they didn't match the      | -->
<!-- |     convention, will have to added back later.                      | -->
<!-- ======================================================================= -->
<!--LICENSE:                                                                 -->
<!--Copyright (c) 2015, Robert Krug & Todor Stoyanov, AASS Research Center,  -->
<!--Orebro University, Sweden                                                -->
<!--All rights reserved.                                                     -->
<!--                                                                         -->
<!--Redistribution and use in source and binary forms, with or without       -->
<!--modification, are permitted provided that the following conditions are   -->
<!--met:                                                                     -->
<!--                                                                         -->
<!--1. Redistributions of source code must retain the above copyright notice,-->
<!--   this list of conditions and the following disclaimer.                 -->
<!--                                                                         -->
<!--2. Redistributions in binary form must reproduce the above copyright     -->
<!--   notice, this list of conditions and the following disclaimer in the   -->
<!--   documentation and/or other materials provided with the distribution.  -->
<!--                                                                         -->
<!--THIS SOFTWARE IS PROVIDED BY THE COPYRIGHT HOLDERS AND CONTRIBUTORS "AS  -->
<!--IS" AND ANY EXPRESS OR IMPLIED WARRANTIES, INCLUDING, BUT NOT LIMITED TO,-->
<!--THE IMPLIED WARRANTIES OF MERCHANTABILITY AND FITNESS FOR A PARTICULAR   -->
<!--PURPOSE ARE DISCLAIMED. IN NO EVENT SHALL THE COPYRIGHT HOLDER OR        -->
<!--CONTRIBUTORS BE LIABLE FOR ANY DIRECT, INDIRECT, INCIDENTAL, SPECIAL,    -->
<!--EXEMPLARY, OR CONSEQUENTIAL DAMAGES (INCLUDING, BUT NOT LIMITED TO,      -->
<!--PROCUREMENT OF SUBSTITUTE GOODS OR SERVICES; LOSS OF USE, DATA, OR       -->
<!--PROFITS; OR BUSINESS INTERRUPTION) HOWEVER CAUSED AND ON ANY THEORY OF   -->
<!--LIABILITY, WHETHER IN CONTRACT, STRICT LIABILITY, OR TORT (INCLUDING     -->
<!--NEGLIGENCE OR OTHERWISE) ARISING IN ANY WAY OUT OF THE USE OF THIS       -->
<!--SOFTWARE, EVEN IF ADVISED OF THE POSSIBILITY OF SUCH DAMAGE.             -->
<robot name="lbr_iiwa" xmlns:xacro="http://www.ros.org/wiki/xacro">
  <!-- Import Rviz colors -->
  <mujoco>
    <compiler meshdir="uhvat_description/visual" balanceinertia="false" discardvisual="false"/>
  </mujoco>
  <material name="Grey">
    <color rgba="0.2 0.2 0.2 1.0"/>
  </material>
  <material name="Orange">
    <color rgba="1.0 0.423529411765 0.0392156862745 1.0"/>
  </material>
  <material name="Blue">
  <color rgba="0.5 0.7 1.0 1.0"/>      
</material>
  <link name="root">
    <inertial>
      <origin rpy="-0.03143 -0.00602 -0.37822" xyz="0.00100 -0.00200 0.29000"/>
      <mass value="4.00000"/>
      <inertia ixx="0.05139" ixy="0" ixz="0" iyy="0.05015" iyz="0" izz="0.04715"/>
    </inertial>
  </link>
  <link name="root1">
    <inertial>
      <mass value="0.01"/>
      <inertia ixx="1e-4" ixy="0.0" ixz="0.0" iyy="1e-4" iyz="0.0" izz="1e-4"/>
    </inertial>
  </link>
  <link name="root2">
    <inertial>
      <mass value="0.01"/>
      <inertia ixx="1e-4" ixy="0.0" ixz="0.0" iyy="1e-4" iyz="0.0" izz="1e-4"/>
    </inertial>
  </link>
  <link name="root3">
    <inertial>
      <mass value="0.01"/>
      <inertia ixx="1e-4" ixy="0.0" ixz="0.0" iyy="1e-4" iyz="0.0" izz="1e-4"/>
    </inertial>
  </link>
  <link name="root4">
    <inertial>
      <mass value="0.01"/>
      <inertia ixx="1e-4" ixy="0.0" ixz="0.0" iyy="1e-4" iyz="0.0" izz="1e-4"/>
    </inertial>
  </link>
  <link name="root5">
    <inertial>
      <mass value="0.01"/>
      <inertia ixx="1e-4" ixy="0.0" ixz="0.0" iyy="1e-4" iyz="0.0" izz="1e-4"/>
    </inertial>
  </link>

  <joint name="x_joint" type="prismatic">
    <parent link="root"/>
    <child link="root1"/>
    <axis xyz="1 0 0"/>
    <limit lower="-5" upper="5"/>
  </joint>
  <joint name="y_joint" type="prismatic">
    <parent link="root1"/>
    <child link="root2"/>
    <axis xyz="0 1 0"/>
    <limit lower="-5" upper="5"/>
  </joint>
  <joint name="z_joint" type="prismatic">
    <parent link="root2"/>
    <child link="root3"/>
    <axis xyz="0 0 1"/>
    <limit lower="-5" upper="5"/>
  </joint>
  <joint name="x_rotation_joint" type="revolute">
    <parent link="root3"/>
    <child link="root4"/>
    <axis xyz="1 0 0"/>
    <limit lower="-3.14" upper="3.14"/>
  </joint>
  <joint name="y_rotation_joint" type="revolute">
    <parent link="root4"/>
    <child link="root5"/>
    <axis xyz="0 1 0"/>
    <limit lower="-3.14" upper="3.14"/>
  </joint>
  <joint name="z_rotation_joint" type="revolute">
    <parent link="root5"/>
    <child link="uhvat_link_0"/>
    <axis xyz="0 0 1"/>
    <origin rpy="-0.00000 -0.00000 1.57079" xyz="0 0 0"/>
    <limit lower="-3.14" upper="3.14"/>
  </joint>

  <link name="uhvat_link_0">
    <inertial>
      <origin rpy="0 0 0" xyz="-1.40846398e-02  9.04628229e-07 -4.91359742e-06"/>
      <mass value="0.05020125376157147"/>
      <inertia ixx="4.61685605e-05" ixy="-7.88272268e-10" ixz="6.84094585e-10" iyy="1.88534477e-05" iyz="2.28758424e-09" izz="4.54452943e-05"/>
    </inertial>
    <visual>
      <origin rpy="0 0 0" xyz="0 0 0"/>
      <geometry>
        <mesh filename="uhvat_description/motor_mount_tiny.stl" scale="1 1 1"/>
      </geometry>
      <material name="Grey"/>
    </visual>
    <collision>
      <origin rpy="0 0 0" xyz="0 0 0"/>
      <geometry>
        <mesh filename="uhvat_description/motor_mount_tiny.stl" scale="1 1 1"/>
      </geometry>
    </collision>
  </link>
  <!-- left finger -->
  <joint name="uhvat_joint_1" type="prismatic">
    <origin rpy="0 0 1.3" xyz="-0.045 -0.075 0"/>
    <parent link="uhvat_link_0"/>
    <child link="uhvat_link_1"/>
    <axis xyz="1 0 0"/>
    <limit effort="2" lower="0.0" upper="0.06" velocity="0.5"/>
    <dynamics damping="0.4" friction="0.4"/>
  </joint>
  <link name="uhvat_link_1">
    <inertial>
      <origin rpy="0 0 0" xyz="-0.01501654  0.02981859  0.01176479"/>
      <mass value="0.020558017345724853"/>
      <inertia ixx="1.10355285e-05" ixy="-3.96153698e-08" ixz="-3.83755623e-09" iyy="2.18604555e-06" iyz="-7.76381797e-07" izz="1.11699254e-05"/>
    </inertial>
    <visual>
      <origin rpy="0 0 0" xyz="0.015 0.025 -0.02"/>
      <geometry>
        <mesh filename="uhvat_description/festolike_finger_tiny.stl" scale="1 1 1"/>
      </geometry>
      <material name="Green"/>
    </visual>
    <collision>
      <origin rpy="0 0 0" xyz="0.015 0.025 -0.02"/>
      <geometry>
        <mesh filename="uhvat_description/festolike_finger_tiny.stl" scale="1 1 1"/>
      </geometry>
    </collision>
  </link>
  <joint name="uhvat_joint_1_tip" type="fixed">
    <origin rpy="0 0 0" xyz="-0.0153 0.074 0.021"/>
    <parent link="uhvat_link_1"/>
    <child link="uhvat_link_1_tip"/>
  </joint>
  <link name="uhvat_link_1_tip">
  </link>
  
  <!-- right finger -->
  <joint name="uhvat_joint_2" type="prismatic">
    <origin rpy="0 0 1.83" xyz="-0.045 0.075 0"/>
    <parent link="uhvat_link_0"/>
    <child link="uhvat_link_2"/>
    <axis xyz="1 0 0"/>
    <limit effort="2" lower="-0.06" upper="0.0" velocity="0.5"/>
    <dynamics damping="0.4" friction="0.4"/>
  </joint>
  <link name="uhvat_link_2">
    <inertial>
      <origin rpy="0 0 0" xyz="-0.01501654  0.02981859  0.01176479"/>
      <mass value="0.020558017345724853"/>
      <inertia ixx="1.10355285e-05" ixy="-3.96153698e-08" ixz="-3.83755623e-09" iyy="2.18604555e-06" iyz="-7.76381797e-07" izz="1.11699254e-05"/>
    </inertial>
    <visual>
      <origin rpy="0 0 0" xyz="0.025 0.025 -0.02"/>
      <geometry>
        <mesh filename="uhvat_description/festolike_finger_tiny.stl" scale="1 1 1"/>
      </geometry>
      <material name="Orange"/>
    </visual>
    <collision>
      <origin rpy="0 0 0" xyz="0.025 0.025 -0.02"/>
      <geometry>
        <mesh filename="uhvat_description/festolike_finger_tiny.stl" scale="1 1 1"/>
      </geometry>
    </collision>
  </link>
  <joint name="uhvat_joint_2_tip" type="fixed">
    <origin rpy="0 0 0" xyz="-0.0153 0.074 0.021"/>
    <parent link="uhvat_link_2"/>
    <child link="uhvat_link_2_tip"/>
  </joint>
  <link name="uhvat_link_2_tip">
  </link>
  <link name="palm_center">
  </link>
  <joint name="palm_center_joint" type="fixed">
    <parent link="uhvat_link_0"/>
    <child link="palm_center"/>
    <origin rpy="3.141592653589793 3.141592653589793 3.141592653589793" xyz="0 0 0.1"/>
  </joint>
</robot>
